<?xml version="1.0" ?>
<!-- =================================================================================== -->
<!-- |    This document was autogenerated by xacro from single_rrbot.urdf.xacro        | -->
<!-- |    EDITING THIS FILE BY HAND IS NOT RECOMMENDED                                 | -->
<!-- =================================================================================== -->
<robot name="single_rrbot" xmlns:xacro="http://www.ros.org/wiki/xacro">
  <!-- Import your models -->
  <material name="RRBOT/black">
    <color rgba="0.0 0.0 0.0 1.0"/>
  </material>
  <material name="RRBOT/blue">
    <color rgba="0.0 0.0 0.8 1.0"/>
  </material>
  <material name="RRBOT/green">
    <color rgba="0.0 0.8 0.0 1.0"/>
  </material>
  <material name="RRBOT/grey">
    <color rgba="0.2 0.2 0.2 1.0"/>
  </material>
  <material name="RRBOT/orange">
    <color rgba="1.0 0.423529411765 0.0392156862745 1.0"/>
  </material>
  <material name="RRBOT/brown">
    <color rgba="0.870588235294 0.811764705882 0.764705882353 1.0"/>
  </material>
  <material name="RRBOT/red">
    <color rgba="0.8 0.0 0.0 1.0"/>
  </material>
  <material name="RRBOT/white">
    <color rgba="1.0 1.0 1.0 1.0"/>
  </material>
  <!-- Build your comprehensive robot -->
  <link name="world"/>
  <gazebo reference="world">
    <static>true</static>
  </gazebo>
  <joint name="single_rrbot_fixed" type="fixed">
    <origin rpy="0 0 0" xyz="0 0 0"/>
    <parent link="world"/>
    <child link="single_rrbot_link1"/>
  </joint>
  <link name="single_rrbot_link1">
    <collision>
      <origin rpy="0 0 0" xyz="0 0 1.0"/>
      <geometry>
        <box size="0.1 0.1 2"/>
      </geometry>
    </collision>
    <visual>
      <origin rpy="0 0 0" xyz="0 0 1.0"/>
      <geometry>
        <box size="0.1 0.1 2"/>
      </geometry>
      <material name="RRBOT/orange"/>
    </visual>
    <inertial>
      <origin rpy="0 0 0" xyz="0 0 1.0"/>
      <mass value="1"/>
      <inertia ixx="1.0" ixy="0.0" ixz="0.0" iyy="1.0" iyz="0.0" izz="1.0"/>
    </inertial>
  </link>
  <joint name="single_rrbot_joint1" type="continuous">
    <parent link="single_rrbot_link1"/>
    <child link="single_rrbot_link2"/>
    <origin rpy="0 0 0" xyz="0 0.1 1.95"/>
    <axis xyz="0 1 0"/>
    <dynamics damping="0.7"/>
  </joint>

  <gazebo>
    <plugin filename="libgazebo_ros2_control.so" name="gazebo_ros2_control">
      <robot_sim_type>gazebo_ros2_control/GazeboSystem</robot_sim_type>
      <parameters>/home/ahcorde/ros2_control_ws_foxy/rrbot.yaml</parameters>
      <control_period>0.001</control_period>
    </plugin>
  </gazebo>

  <link name="single_rrbot_link2">
    <collision>
      <origin rpy="0 0 0" xyz="0 0 0.45"/>
      <geometry>
        <box size="0.1 0.1 1"/>
      </geometry>
    </collision>
    <visual>
      <origin rpy="0 0 0" xyz="0 0 0.45"/>
      <geometry>
        <box size="0.1 0.1 1"/>
      </geometry>
      <material name="RRBOT/black"/>
    </visual>
    <inertial>
      <origin rpy="0 0 0" xyz="0 0 0.45"/>
      <mass value="1"/>
      <inertia ixx="1.0" ixy="0.0" ixz="0.0" iyy="1.0" iyz="0.0" izz="1.0"/>
    </inertial>
  </link>
  <joint name="single_rrbot_joint2" type="continuous">
    <parent link="single_rrbot_link2"/>
    <child link="single_rrbot_link3"/>
    <origin rpy="0 0 0" xyz="0 0.1 0.9"/>
    <axis xyz="0 1 0"/>
    <dynamics damping="0.7"/>
  </joint>
  <link name="single_rrbot_link3">
    <collision>
      <origin rpy="0 0 0" xyz="0 0 0.45"/>
      <geometry>
        <box size="0.1 0.1 1"/>
      </geometry>
    </collision>
    <visual>
      <origin rpy="0 0 0" xyz="0 0 0.45"/>
      <geometry>
        <box size="0.1 0.1 1"/>
      </geometry>
      <material name="RRBOT/orange"/>
    </visual>
    <inertial>
      <origin rpy="0 0 0" xyz="0 0 0.45"/>
      <mass value="1"/>
      <inertia ixx="1.0" ixy="0.0" ixz="0.0" iyy="1.0" iyz="0.0" izz="1.0"/>
    </inertial>
  </link>
  <joint name="single_rrbot_hokuyo_joint" type="fixed">
    <axis xyz="0 1 0"/>
    <origin rpy="0 0 0" xyz="0 0 0.975"/>
    <parent link="single_rrbot_link3"/>
    <child link="single_rrbot_hokuyo_link"/>
  </joint>
  <link name="single_rrbot_hokuyo_link">
    <collision>
      <origin rpy="0 0 0" xyz="0 0 0"/>
      <geometry>
        <box size="0.1 0.1 0.1"/>
      </geometry>
    </collision>
    <visual>
      <origin rpy="0 0 0" xyz="0 0 0"/>
      <geometry>
        <box size="0.1 0.1 0.1"/>
      </geometry>
    </visual>
    <inertial>
      <mass value="1e-5"/>
      <origin rpy="0 0 0" xyz="0 0 0"/>
      <inertia ixx="1e-6" ixy="0" ixz="0" iyy="1e-6" iyz="0" izz="1e-6"/>
    </inertial>
  </link>
  <joint name="single_rrbot_camera_joint" type="fixed">
    <axis xyz="0 1 0"/>
    <origin rpy="0 0 0" xyz="0.05 0 0.9"/>
    <parent link="single_rrbot_link3"/>
    <child link="single_rrbot_camera_link"/>
  </joint>
  <link name="single_rrbot_camera_link">
    <collision>
      <origin rpy="0 0 0" xyz="0 0 0"/>
      <geometry>
        <box size="0.05 0.05 0.05"/>
      </geometry>
    </collision>
    <visual>
      <origin rpy="0 0 0" xyz="0 0 0"/>
      <geometry>
        <box size="0.05 0.05 0.05"/>
      </geometry>
      <material name="RRBOT/red"/>
    </visual>
    <inertial>
      <mass value="1e-5"/>
      <origin rpy="0 0 0" xyz="0 0 0"/>
      <inertia ixx="1e-6" ixy="0" ixz="0" iyy="1e-6" iyz="0" izz="1e-6"/>
    </inertial>
  </link>
  <transmission name="single_rrbot_tran1">
    <type>transmission_interface/SimpleTransmission</type>
    <joint name="single_rrbot_joint1">
      <hardwareInterface>hardware_interface/PositionJointInterface</hardwareInterface>
    </joint>
    <actuator name="single_rrbot_motor1">
      <hardwareInterface>hardware_interface/PositionJointInterface</hardwareInterface>
      <mechanicalReduction>1</mechanicalReduction>
    </actuator>
  </transmission>
  <transmission name="single_rrbot_tran2">
    <type>transmission_interface/SimpleTransmission</type>
    <joint name="single_rrbot_joint2">
      <hardwareInterface>hardware_interface/PositionJointInterface</hardwareInterface>
    </joint>
    <actuator name="single_rrbot_motor2">
      <hardwareInterface>hardware_interface/PositionJointInterface</hardwareInterface>
      <mechanicalReduction>1</mechanicalReduction>
    </actuator>
  </transmission>
  <gazebo reference="single_rrbot_link1">
    <material>Gazebo/Orange</material>
  </gazebo>
  <gazebo reference="single_rrbot_link2">
    <mu1>0.2</mu1>
    <mu2>0.2</mu2>
    <material>Gazebo/Black</material>
  </gazebo>
  <gazebo reference="single_rrbot_link3">
    <mu1>0.2</mu1>
    <mu2>0.2</mu2>
    <material>Gazebo/Orange</material>
  </gazebo>
  <gazebo reference="single_rrbot_camera_link">
    <mu1>0.2</mu1>
    <mu2>0.2</mu2>
    <material>Gazebo/Red</material>
  </gazebo>
</robot>
